./ci/test_run_all.sh
Setting specific values in env
Fallback to default values in env (if not yet set)
CCACHE_TEMPDIR=/tmp/.ccache-temp
BASE_OUTDIR=/tmp/cirrus-ci-build/ci/scratch/out/x86_64-pc-linux-gnu
TSAN_OPTIONS=suppressions=/tmp/cirrus-ci-build/test/sanitizer_suppressions/tsan:halt_on_error=1:log_path=/tmp/cirrus-ci-build/ci/scratch/sanitizer-output/tsan
CCACHE_SIZE=200M
CCACHE_DIR=/tmp/ccache_dir
BASE_BUILD_DIR=/tmp/cirrus-ci-build/ci/scratch/build
BASE_ROOT_DIR=/tmp/cirrus-ci-build
CCACHE_COMPRESS=1
ASAN_OPTIONS=detect_stack_use_after_return=1:check_initialization_order=1:strict_init_order=1
LSAN_OPTIONS=suppressions=/tmp/cirrus-ci-build/test/sanitizer_suppressions/lsan
BOOST_TEST_RANDOM=1
BITCOIN_CONFIG=--enable-usdt --enable-zmq --with-incompatible-bdb --with-gui=qt5 CPPFLAGS='-DARENA_DEBUG -DDEBUG_LOCKORDER' --with-sanitizers=address,integer,undefined CC=clang CXX=clang++
UBSAN_OPTIONS=suppressions=/tmp/cirrus-ci-build/test/sanitizer_suppressions/ubsan:print_stacktrace=1:halt_on_error=1:report_error_type=1
BASE_SCRATCH_DIR=/tmp/cirrus-ci-build/ci/scratch
CCACHE_NOHASHDIR=1
LC_ALL=C.UTF-8
PREVIOUS_RELEASES_DIR=/tmp/cirrus-ci-build/releases/x86_64-pc-linux-gnu
DEBIAN_FRONTEND=noninteractive
Running on host system without docker wrapper
Repository: 'deb https://ppa.launchpadcontent.net/hadret/bpfcc/ubuntu/ jammy main'
Description:
Port of latest version of bpfcc-tools to Ubuntu 18.04+.
More info: https://launchpad.net/~hadret/+archive/ubuntu/bpfcc
Adding repository.
Adding deb entry to /etc/apt/sources.list.d/hadret-ubuntu-bpfcc-jammy.list
Adding disabled deb-src entry to /etc/apt/sources.list.d/hadret-ubuntu-bpfcc-jammy.list
Traceback (most recent call last):
  File "/usr/lib/python3/dist-packages/httplib2/__init__.py", line 1393, in _conn_request
    response = conn.getresponse()
  File "/usr/lib/python3.10/http/client.py", line 1374, in getresponse
    response.begin()
  File "/usr/lib/python3.10/http/client.py", line 318, in begin
    version, status, reason = self._read_status()
  File "/usr/lib/python3.10/http/client.py", line 287, in _read_status
    raise RemoteDisconnected("Remote end closed connection without"
http.client.RemoteDisconnected: Remote end closed connection without response

During handling of the above exception, another exception occurred:

Traceback (most recent call last):
  File "/usr/bin/add-apt-repository", line 364, in <module>
    sys.exit(0 if addaptrepo.main() else 1)
  File "/usr/bin/add-apt-repository", line 357, in main
    shortcut.add()
  File "/usr/lib/python3/dist-packages/softwareproperties/shortcuthandler.py", line 222, in add
    self.add_key()
  File "/usr/lib/python3/dist-packages/softwareproperties/shortcuthandler.py", line 398, in add_key
    if not all((self.trustedparts_file, self.trustedparts_content)):
  File "/usr/lib/python3/dist-packages/softwareproperties/ppa.py", line 141, in trustedparts_content
    key = self.lpppa.getSigningKeyData()
  File "/usr/lib/python3/dist-packages/lazr/restfulclient/resource.py", line 592, in __call__
    response, content = self.root._browser._request(
  File "/usr/lib/python3/dist-packages/lazr/restfulclient/_browser.py", line 389, in _request
    response, content = self._request_and_retry(
  File "/usr/lib/python3/dist-packages/lazr/restfulclient/_browser.py", line 359, in _request_and_retry
    response, content = self._connection.request(
  File "/usr/lib/python3/dist-packages/httplib2/__init__.py", line 1725, in request
    (response, content) = self._request(
  File "/usr/lib/python3/dist-packages/launchpadlib/launchpad.py", line 144, in _request
    response, content = super(LaunchpadOAuthAwareHttp, self)._request(
  File "/usr/lib/python3/dist-packages/lazr/restfulclient/_browser.py", line 184, in _request
    return super(RestfulHttp, self)._request(
  File "/usr/lib/python3/dist-packages/httplib2/__init__.py", line 1441, in _request
    (response, content) = self._conn_request(conn, request_uri, method, body, headers)
  File "/usr/lib/python3/dist-packages/httplib2/__init__.py", line 1402, in _conn_request
    conn.connect()
  File "/usr/lib/python3/dist-packages/httplib2/__init__.py", line 1153, in connect
    sock.connect((self.host, self.port))
TimeoutError: [Errno 110] Connection timed out
